<?xml version="1.0"?>
<robot xmlns:xacro="http://www.ros.org/wiki/xacro" name="robotic_hand">

  <!-- Define macros for reusable components -->
  <xacro:property name="default_inertial_mass" value="0.1"/>
  <xacro:property name="default_inertial_inertia" value="0.001"/>

  <!-- Base Link -->
  <link name="world"></link>

  <!-- Base Joint -->
  <joint name="base_to_hand_joint" type="fixed">
    <parent link="world"/>
    <child link="hand_link"/>
    <origin xyz="0 0 0.1" rpy="0 0 0"/>
  </joint>

  <!-- Hand Link -->
  <link name="hand_link">
    <inertial>
      <mass value="0.5"/>
      <origin xyz="0 0 0"/>
      <inertia ixx="0.002" ixy="0" ixz="0" iyy="0.002" iyz="0" izz="0.002"/>
    </inertial>
    <visual>
      <origin xyz="0 0 0" rpy="0 0 0"/>
      <geometry>
        <mesh filename="file://$(find robotic_hand)/meshes/palma_dorso_link.STL"/>
      </geometry>
      <material name="hand_material">
        <color rgba="0.8 0.8 0.8 1.0"/>
      </material>
    </visual>
    <collision>
      <origin xyz="0 0 0" rpy="0 0 0"/>
      <geometry>
        <mesh filename="file://$(find robotic_hand)/meshes/palma_dorso_link.STL"/>
      </geometry>
    </collision>
  </link>

  <!-- Gazebo Plugin Moved Here -->
  <gazebo>
    <plugin filename="gz_ros2_control-system" name="gz_ros2_control::GazeboSimROS2ControlPlugin">
      <parameters>$(find robotic_hand)/config/hand_controllers.yaml</parameters>
      <ros>
        <remapping>/controller_manager/robot_description:=/robot_description</remapping>
      </ros>
    </plugin>
  </gazebo>

  <!-- Fingers Macro Definition -->
  <xacro:macro name="finger" params="name link0_mesh link1_mesh link2_mesh mass inertia_xyz inertia_rpy xyz rpy">
    <link name="${name}_link0">
      <inertial>
        <mass value="${mass}"/>
        <origin xyz="${inertia_xyz}" rpy="${inertia_rpy}"/>
        <inertia ixx="0.001" ixy="0" ixz="0" iyy="0.001" iyz="0" izz="0.001"/>
      </inertial>
      <visual>
        <origin xyz="0 0 0" rpy="0 0 0"/>
        <geometry>
          <mesh filename="file://$(find robotic_hand)/meshes/${link0_mesh}.STL"/>
        </geometry>
      </visual>
    </link>
    <joint name="${name}_joint0" type="revolute">
      <parent link="hand_link"/>
      <child link="${name}_link0"/>
      <origin xyz="${xyz}" rpy="${rpy}"/>
      <axis xyz="0 0 1"/>
      <limit lower="-1.57" upper="1.57" effort="1.0" velocity="1.5"/>
    </joint>
  </xacro:macro>

  <!-- Define the fingers -->
  <xacro:finger name="index_finger" link0_mesh="indice_link0" link1_mesh="indice_link1" link2_mesh="indice_link2" mass="0.05" inertia_xyz="0 0 0" inertia_rpy="0 0 0" xyz="0.02 0.05 0" rpy="0 0 0"/>
  <xacro:finger name="middle_finger" link0_mesh="medio_link0" link1_mesh="medio_link1" link2_mesh="medio_link2" mass="0.05" inertia_xyz="0 0 0" inertia_rpy="0 0 0" xyz="0.0 0.05 0" rpy="0 0 0"/>
  <xacro:finger name="ring_finger" link0_mesh="anular_link0" link1_mesh="anular_link1" link2_mesh="anular_link2" mass="0.05" inertia_xyz="0 0 0" inertia_rpy="0 0 0" xyz="-0.02 0.05 0" rpy="0 0 0"/>
  <xacro:finger name="pinky_finger" link0_mesh="menique_link0" link1_mesh="menique_link1" link2_mesh="menique_link2" mass="0.05" inertia_xyz="0 0 0" inertia_rpy="0 0 0" xyz="-0.04 0.05 0" rpy="0 0 0"/>
  <xacro:finger name="thumb_finger" link0_mesh="pulgar_link0" link1_mesh="pulgar_link1" link2_mesh="pulgar_link2" mass="0.05" inertia_xyz="0 0 0" inertia_rpy="0 0 0" xyz="0.02 -0.02 0" rpy="0 0 -0.2"/>

</robot>
