<sdf version='1.7'>
  <model name='robotic_hand'>

    <plugin name="ros2_control_plugin" filename="libgazebo_ros2_control.so">
      <robot_namespace>/robotic_hand</robot_namespace>
      <control_type>effort_controllers/JointTrajectoryController</control_type>
      <joint>
          <name>joint_indice_0</name>
          <hardwareInterface>position</hardwareInterface>
      </joint>
      <joint>
          <name>joint_indice_1</name>
          <hardwareInterface>position</hardwareInterface>
      </joint>
      <joint>
          <name>joint_indice_2</name>
          <hardwareInterface>position</hardwareInterface>
      </joint>
    </plugin>


    <ros2_control name="GazeboSystem" type="system">
      <hardware>
        <plugin>gz_ros2_control/GazeboSimSystem</plugin>
      </hardware>
      <joint name="joint_indice_0">
        <command_interface name="position">
          <param name="min">-3.14</param>
          <param name="max">3.14</param>
        </command_interface>
        <state_interface name="position">
          <param name="initial_value">0</param>
        </state_interface>
      </joint>
      <joint name="joint_indice_1">
        <command_interface name="position">
          <param name="min">-3.14</param>
          <param name="max">3.14</param>
        </command_interface>
        <state_interface name="position">
          <param name="initial_value">0</param>
        </state_interface>
      </joint>
      <joint name="joint_indice_2">
        <command_interface name="position">
          <param name="min">-3.14</param>
          <param name="max">3.14</param>
        </command_interface>
        <state_interface name="position">
          <param name="initial_value">0</param>
        </state_interface>
      </joint>
    </ros2_control>
    <gazebo>
      <!-- Joint state publisher -->
      <plugin filename="gz_ros2_control-system" name="gz_ros2_control::GazeboSimROS2ControlPlugin">
        <parameters>/home/pablo_kevin/ros2_robotic_hand_ws/install/robotic_hand/share/robotic_hand/config/</parameters>
      </plugin>
    </gazebo>
 
    <link name='base_link'>
      <inertial>
        <pose>0.01266 0.007711 0.22272 0 -0 0</pose>
        <mass>0.20247</mass>
        <inertia>
          <ixx>0.0014611</ixx>
          <ixy>3.6753e-05</ixy>
          <ixz>-4.2033e-06</ixz>
          <iyy>0.00098384</iyy>
          <iyz>-0.00016151</iyz>
          <izz>0.00050623</izz>
        </inertia>
      </inertial>
      <collision name='base_link_fixed_joint_lump__palma_dorso_link_collision'>
        <pose>0 0 0.1 0 -0 0</pose>
        <geometry>
          <mesh>
            <scale>1 1 1</scale>
            <uri>../meshes/palma_dorso_link.STL</uri>
          </mesh>
        </geometry>
      </collision>
      <collision name='base_link_fixed_joint_lump__conectores_links_collision_1'>
        <pose>0.00762 -0.225244 0.236582 1.5708 -0 0</pose>
        <geometry>
          <mesh>
            <scale>1 1 1</scale>
            <uri>../meshes/conectores_links.STL</uri>
          </mesh>
        </geometry>
      </collision>
      <visual name='base_link_fixed_joint_lump__palma_dorso_link_visual'>
  <material>
    <ambient>0.25 0.00 0.30 1.0</ambient>
    <diffuse>0.25 0.00 0.30 1.0</diffuse>
    <specular>0.5 0.5 0.5 1.0</specular>
    <emissive>0 0 0 1.0</emissive>
  </material>
        <pose>0 0 0.1 0 -0 0</pose>
        <geometry>
          <mesh>
            <scale>1 1 1</scale>
            <uri>../meshes/palma_dorso_link.STL</uri>
          </mesh>
        </geometry>
      </visual>
      <visual name='base_link_fixed_joint_lump__conectores_links_visual_1'>
  <material>
    <ambient>0.25 0.00 0.30 1.0</ambient>
    <diffuse>0.25 0.00 0.30 1.0</diffuse>
    <specular>0.5 0.5 0.5 1.0</specular>
    <emissive>0 0 0 1.0</emissive>
  </material>
        <pose>0.00762 -0.225244 0.236582 1.5708 -0 0</pose>
        <geometry>
          <mesh>
            <scale>1 1 1</scale>
            <uri>../meshes/conectores_links.STL</uri>
          </mesh>
        </geometry>
      </visual>
    </link>
    <joint name='joint_anular_0' type='revolute'>
      <pose relative_to='base_link'>0.017396 -0.10601 0.079212 1.5708 -0 0.13729</pose>
      <parent>base_link</parent>
      <child>anular_link0</child>
      <axis>
        <xyz>0 1 0</xyz>
        <limit>
          <lower>-1e+16</lower>
          <upper>1e+16</upper>
        </limit>
        <dynamics>
          <spring_reference>0</spring_reference>
          <spring_stiffness>0</spring_stiffness>
        </dynamics>
      </axis>
    </joint>
    <link name='anular_link0'>
      <pose relative_to='joint_anular_0'>0 0 0 0 -0 0</pose>
      <inertial>
        <pose>-0.000147 -0.012697 -0.017313 0 -0 0</pose>
        <mass>0.0126336</mass>
        <inertia>
          <ixx>2.06877e-06</ixx>
          <ixy>-1.20016e-09</ixy>
          <ixz>-9.77141e-09</ixz>
          <iyy>1.7254e-06</iyy>
          <iyz>6.07253e-09</iyz>
          <izz>1.00343e-06</izz>
        </inertia>
      </inertial>
      <collision name='anular_link0_collision'>
        <pose>0 0 0 0 -0 0</pose>
        <geometry>
          <mesh>
            <scale>1 1 1</scale>
            <uri>../meshes/anular_link0.STL</uri>
          </mesh>
        </geometry>
      </collision>
      <visual name='anular_link0_visual'>
  <material>
    <ambient>0.25 0.00 0.30 1.0</ambient>
    <diffuse>0.25 0.00 0.30 1.0</diffuse>
    <specular>0.5 0.5 0.5 1.0</specular>
    <emissive>0 0 0 1.0</emissive>
  </material>
        <pose>0 0 0 0 -0 0</pose>
        <geometry>
          <mesh>
            <scale>1 1 1</scale>
            <uri>../meshes/anular_link0.STL</uri>
          </mesh>
        </geometry>
      </visual>
    </link>
    <joint name='joint_anular_1' type='revolute'>
      <pose relative_to='anular_link0'>-2.1e-05 -0.000351 -0.033417 0.000848 -0.099197 0.000147</pose>
      <parent>anular_link0</parent>
      <child>anular_link1</child>
      <axis>
        <xyz>0.000146 1 -0.000863</xyz>
        <limit>
          <lower>-1e+16</lower>
          <upper>1e+16</upper>
        </limit>
        <dynamics>
          <spring_reference>0</spring_reference>
          <spring_stiffness>0</spring_stiffness>
        </dynamics>
      </axis>
    </joint>
    <link name='anular_link1'>
      <pose relative_to='joint_anular_1'>0 0 0 0 -0 0</pose>
      <inertial>
        <pose>-0.000639 -0.012513 -0.016258 0 -0 0</pose>
        <mass>0.010609</mass>
        <inertia>
          <ixx>1.3028e-06</ixx>
          <ixy>-1.4775e-10</ixy>
          <ixz>4.3567e-08</ixz>
          <iyy>1.2133e-06</iyy>
          <iyz>-3.0441e-10</iyz>
          <izz>6.683e-07</izz>
        </inertia>
      </inertial>
      <collision name='anular_link1_collision'>
        <pose>0 0 0 0 -0 0</pose>
        <geometry>
          <mesh>
            <scale>1 1 1</scale>
            <uri>../meshes/anular_link1.STL</uri>
          </mesh>
        </geometry>
      </collision>
      <visual name='anular_link1_visual'>
  <material>
    <ambient>0.25 0.00 0.30 1.0</ambient>
    <diffuse>0.25 0.00 0.30 1.0</diffuse>
    <specular>0.5 0.5 0.5 1.0</specular>
    <emissive>0 0 0 1.0</emissive>
  </material>
        <pose>0 0 0 0 -0 0</pose>
        <geometry>
          <mesh>
            <scale>1 1 1</scale>
            <uri>../meshes/anular_link1.STL</uri>
          </mesh>
        </geometry>
      </visual>
    </link>
    <joint name='joint_anular_2' type='revolute'>
      <pose relative_to='anular_link1'>0 -0.000424 -0.033504 -0.000865 0.06986 -0.000206</pose>
      <parent>anular_link1</parent>
      <child>anular_link2</child>
      <axis>
        <xyz>0 1 0</xyz>
        <limit>
          <lower>-1e+16</lower>
          <upper>1e+16</upper>
        </limit>
        <dynamics>
          <spring_reference>0</spring_reference>
          <spring_stiffness>0</spring_stiffness>
        </dynamics>
      </axis>
    </joint>
    <link name='anular_link2'>
      <pose relative_to='joint_anular_2'>0 0 0 0 -0 0</pose>
      <inertial>
        <pose>-0.000444 -0.012109 -0.014311 0 -0 0</pose>
        <mass>0.00947096</mass>
        <inertia>
          <ixx>1.12538e-06</ixx>
          <ixy>-6.25777e-10</ixy>
          <ixz>3.16594e-08</ixz>
          <iyy>1.11933e-06</iyy>
          <iyz>-3.97943e-10</iyz>
          <izz>4.39896e-07</izz>
        </inertia>
      </inertial>
      <collision name='anular_link2_collision'>
        <pose>0 0 0 0 -0 0</pose>
        <geometry>
          <mesh>
            <scale>1 1 1</scale>
            <uri>../meshes/anular_link2.STL</uri>
          </mesh>
        </geometry>
      </collision>
      <visual name='anular_link2_visual'>
  <material>
    <ambient>0.25 0.00 0.30 1.0</ambient>
    <diffuse>0.25 0.00 0.30 1.0</diffuse>
    <specular>0.5 0.5 0.5 1.0</specular>
    <emissive>0 0 0 1.0</emissive>
  </material>
        <pose>0 0 0 0 -0 0</pose>
        <geometry>
          <mesh>
            <scale>1 1 1</scale>
            <uri>../meshes/anular_link2.STL</uri>
          </mesh>
        </geometry>
      </visual>
    </link>
    <joint name='joint_indice_0' type='revolute'>
      <pose relative_to='base_link'>0.017381 -0.10655 0.111803 1.5708 0 0.09642</pose>
      <parent>base_link</parent>
      <child>indice_link0</child>
      <axis>
        <xyz>0 1 0</xyz>
        <limit>
          <lower>-1e+16</lower>
          <upper>1e+16</upper>
        </limit>
        <dynamics>
          <spring_reference>0</spring_reference>
          <spring_stiffness>0</spring_stiffness>
        </dynamics>
      </axis>
    </joint>
    <link name='indice_link0'>
      <pose relative_to='joint_indice_0'>0 0 0 0 -0 0</pose>
      <inertial>
        <pose>-0.000138 0.012553 -0.016706 0 -0 0</pose>
        <mass>0.0112932</mass>
        <inertia>
          <ixx>1.70111e-06</ixx>
          <ixy>-1.07101e-09</ixy>
          <ixz>-8.52503e-09</ixz>
          <iyy>1.39435e-06</iyy>
          <iyz>1.09842e-09</iyz>
          <izz>8.46994e-07</izz>
        </inertia>
      </inertial>
      <collision name='indice_link0_collision'>
        <pose>0 0 0 0 -0 0</pose>
        <geometry>
          <mesh>
            <scale>1 1 1</scale>
            <uri>../meshes/indice_link0.STL</uri>
          </mesh>
        </geometry>
      </collision>
      <visual name='indice_link0_visual'>
  <material>
    <ambient>0.25 0.00 0.30 1.0</ambient>
    <diffuse>0.25 0.00 0.30 1.0</diffuse>
    <specular>0.5 0.5 0.5 1.0</specular>
    <emissive>0 0 0 1.0</emissive>
  </material>
        <pose>0 0 0 0 -0 0</pose>
        <geometry>
          <mesh>
            <scale>1 1 1</scale>
            <uri>../meshes/indice_link0.STL</uri>
          </mesh>
        </geometry>
      </visual>
    </link>
    <joint name='joint_indice_1' type='revolute'>
      <pose relative_to='indice_link0'>0 0.000534 -0.032043 -0.0051 -0.087262 0</pose>
      <parent>indice_link0</parent>
      <child>indice_link1</child>
      <axis>
        <xyz>0 0.99999 0.0051</xyz>
        <limit>
          <lower>-0.95993</lower>
          <upper>0</upper>
          <effort>0</effort>
          <velocity>0</velocity>
        </limit>
        <dynamics>
          <spring_reference>0</spring_reference>
          <spring_stiffness>0</spring_stiffness>
        </dynamics>
      </axis>
    </joint>
    <link name='indice_link1'>
      <pose relative_to='joint_indice_1'>0 0 0 0 -0 0</pose>
      <inertial>
        <pose>-0.000615 0.011916 -0.015288 0 -0 0</pose>
        <mass>0.0094502</mass>
        <inertia>
          <ixx>1.06519e-06</ixx>
          <ixy>-3.7385e-10</ixy>
          <ixz>3.33799e-08</ixz>
          <iyy>9.75778e-07</iyy>
          <iyz>2.66689e-09</iyz>
          <izz>5.57819e-07</izz>
        </inertia>
      </inertial>
      <collision name='indice_link1_collision'>
        <pose>0 0 0 0 -0 0</pose>
        <geometry>
          <mesh>
            <scale>1 1 1</scale>
            <uri>../meshes/indice_link1.STL</uri>
          </mesh>
        </geometry>
      </collision>
      <visual name='indice_link1_visual'>
  <material>
    <ambient>0.25 0.00 0.30 1.0</ambient>
    <diffuse>0.25 0.00 0.30 1.0</diffuse>
    <specular>0.5 0.5 0.5 1.0</specular>
    <emissive>0 0 0 1.0</emissive>
  </material>
        <pose>0 0 0 0 -0 0</pose>
        <geometry>
          <mesh>
            <scale>1 1 1</scale>
            <uri>../meshes/indice_link1.STL</uri>
          </mesh>
        </geometry>
      </visual>
    </link>
    <joint name='joint_indice_2' type='revolute'>
      <pose relative_to='indice_link1'>0 0.001236 -0.031738 0.005116 -0.079246 -0.000405</pose>
      <parent>indice_link1</parent>
      <child>indice_link2</child>
      <axis>
        <xyz>0 1 0</xyz>
        <limit>
          <lower>0</lower>
          <upper>1.1868</upper>
          <effort>0</effort>
          <velocity>0</velocity>
        </limit>
        <dynamics>
          <spring_reference>0</spring_reference>
          <spring_stiffness>0</spring_stiffness>
        </dynamics>
      </axis>
    </joint>
    <link name='indice_link2'>
      <pose relative_to='joint_indice_2'>0 0 0 0 -0 0</pose>
      <inertial>
        <pose>-0.000414 0.01074 -0.013386 0 -0 0</pose>
        <mass>0.00844698</mass>
        <inertia>
          <ixx>9.20898e-07</ixx>
          <ixy>2.2781e-11</ixy>
          <ixz>2.33875e-08</ixz>
          <iyy>9.06546e-07</iyy>
          <iyz>-9.81161e-10</iyz>
          <izz>3.65181e-07</izz>
        </inertia>
      </inertial>
      <collision name='indice_link2_collision'>
        <pose>0 0 0 0 -0 0</pose>
        <geometry>
          <mesh>
            <scale>1 1 1</scale>
            <uri>../meshes/indice_link2.STL</uri>
          </mesh>
        </geometry>
      </collision>
      <visual name='indice_link2_visual'>
  <material>
    <ambient>0.25 0.00 0.30 1.0</ambient>
    <diffuse>0.25 0.00 0.30 1.0</diffuse>
    <specular>0.5 0.5 0.5 1.0</specular>
    <emissive>0 0 0 1.0</emissive>
  </material>
        <pose>0 0 0 0 -0 0</pose>
        <geometry>
          <mesh>
            <scale>1 1 1</scale>
            <uri>../meshes/indice_link2.STL</uri>
          </mesh>
        </geometry>
      </visual>
    </link>
    <joint name='joint_medio_0' type='revolute'>
      <pose relative_to='base_link'>0.017396 -0.10571 0.1 1.5708 -0 0.12292</pose>
      <parent>base_link</parent>
      <child>medio_link0</child>
      <axis>
        <xyz>0 1 0</xyz>
        <limit>
          <lower>-1e+16</lower>
          <upper>1e+16</upper>
        </limit>
        <dynamics>
          <spring_reference>0</spring_reference>
          <spring_stiffness>0</spring_stiffness>
        </dynamics>
      </axis>
    </joint>
    <link name='medio_link0'>
      <pose relative_to='joint_medio_0'>0 0 0 0 -0 0</pose>
      <inertial>
        <pose>-0.000157 -0.004676 -0.017777 0 -0 0</pose>
        <mass>0.0148708</mass>
        <inertia>
          <ixx>2.70022e-06</ixx>
          <ixy>-1.50316e-09</ixy>
          <ixz>-1.3278e-08</ixz>
          <iyy>2.29788e-06</iyy>
          <iyz>8.77395e-09</iyz>
          <izz>1.24182e-06</izz>
        </inertia>
      </inertial>
      <collision name='medio_link0_collision'>
        <pose>0 0 0 0 -0 0</pose>
        <geometry>
          <mesh>
            <scale>1 1 1</scale>
            <uri>../meshes/medio_link0.STL</uri>
          </mesh>
        </geometry>
      </collision>
      <visual name='medio_link0_visual'>
  <material>
    <ambient>0.25 0.00 0.30 1.0</ambient>
    <diffuse>0.25 0.00 0.30 1.0</diffuse>
    <specular>0.5 0.5 0.5 1.0</specular>
    <emissive>0 0 0 1.0</emissive>
  </material>
        <pose>0 0 0 0 -0 0</pose>
        <geometry>
          <mesh>
            <scale>1 1 1</scale>
            <uri>../meshes/medio_link0.STL</uri>
          </mesh>
        </geometry>
      </visual>
    </link>
    <joint name='joint_medio_1' type='revolute'>
      <pose relative_to='medio_link0'>-2.1e-05 0 -0.03524 0 -0.001265 0</pose>
      <parent>medio_link0</parent>
      <child>medio_link1</child>
      <axis>
        <xyz>0 1 0</xyz>
        <limit>
          <lower>-1e+16</lower>
          <upper>1e+16</upper>
        </limit>
        <dynamics>
          <spring_reference>0</spring_reference>
          <spring_stiffness>0</spring_stiffness>
        </dynamics>
      </axis>
    </joint>
    <link name='medio_link1'>
      <pose relative_to='joint_medio_1'>0 0 0 0 -0 0</pose>
      <inertial>
        <pose>-0.000643 -0.004885 -0.017081 0 -0 0</pose>
        <mass>0.0121315</mass>
        <inertia>
          <ixx>1.64138e-06</ixx>
          <ixy>-1.95095e-10</ixy>
          <ixz>5.14142e-08</ixz>
          <iyy>1.54301e-06</iyy>
          <iyz>5.52304e-10</iyz>
          <izz>8.12468e-07</izz>
        </inertia>
      </inertial>
      <collision name='medio_link1_collision'>
        <pose>0 0 0 0 -0 0</pose>
        <geometry>
          <mesh>
            <scale>1 1 1</scale>
            <uri>../meshes/medio_link1.STL</uri>
          </mesh>
        </geometry>
      </collision>
      <visual name='medio_link1_visual'>
  <material>
    <ambient>0.25 0.00 0.30 1.0</ambient>
    <diffuse>0.25 0.00 0.30 1.0</diffuse>
    <specular>0.5 0.5 0.5 1.0</specular>
    <emissive>0 0 0 1.0</emissive>
  </material>
        <pose>0 0 0 0 -0 0</pose>
        <geometry>
          <mesh>
            <scale>1 1 1</scale>
            <uri>../meshes/medio_link1.STL</uri>
          </mesh>
        </geometry>
      </visual>
    </link>
    <joint name='joint_medio_2' type='revolute'>
      <pose relative_to='medio_link1'>0 0 -0.035366 -0.005044 -0.01913 -0.000914</pose>
      <parent>medio_link1</parent>
      <child>medio_link2</child>
      <axis>
        <xyz>0.000914 -0.999987 -0.005061</xyz>
        <limit>
          <lower>-1e+16</lower>
          <upper>1e+16</upper>
        </limit>
        <dynamics>
          <spring_reference>0</spring_reference>
          <spring_stiffness>0</spring_stiffness>
        </dynamics>
      </axis>
    </joint>
    <link name='medio_link2'>
      <pose relative_to='joint_medio_2'>0 0 0 0 -0 0</pose>
      <inertial>
        <pose>-0.005047 0.007266 0.087066 0 -0 0</pose>
        <mass>0.20247</mass>
        <inertia>
          <ixx>0.00145186</ixx>
          <ixy>5.30453e-05</ixy>
          <ixz>9.35133e-05</ixz>
          <iyy>0.000985511</iyy>
          <iyz>-0.000154434</iyz>
          <izz>0.000513804</izz>
        </inertia>
      </inertial>
      <collision name='medio_link2_collision'>
        <pose>0 0 0 0 -0 0</pose>
        <geometry>
          <mesh>
            <scale>1 1 1</scale>
            <uri>../meshes/medio_link2.STL</uri>
          </mesh>
        </geometry>
      </collision>
      <visual name='medio_link2_visual'>
  <material>
    <ambient>0.25 0.00 0.30 1.0</ambient>
    <diffuse>0.25 0.00 0.30 1.0</diffuse>
    <specular>0.5 0.5 0.5 1.0</specular>
    <emissive>0 0 0 1.0</emissive>
  </material>
        <pose>0 0 0 0 -0 0</pose>
        <geometry>
          <mesh>
            <scale>1 1 1</scale>
            <uri>../meshes/medio_link2.STL</uri>
          </mesh>
        </geometry>
      </visual>
    </link>
    <joint name='joint_menique_0' type='revolute'>
      <pose relative_to='base_link'>0.018096 -0.11691 0.049705 1.5708 -0 0</pose>
      <parent>base_link</parent>
      <child>menique_link0</child>
      <axis>
        <xyz>0 1 0</xyz>
        <limit>
          <lower>-1e+16</lower>
          <upper>1e+16</upper>
        </limit>
        <dynamics>
          <spring_reference>0</spring_reference>
          <spring_stiffness>0</spring_stiffness>
        </dynamics>
      </axis>
    </joint>
    <link name='menique_link0'>
      <pose relative_to='joint_menique_0'>0 0 0 0 -0 0</pose>
      <inertial>
        <pose>-0.000147 -0.011566 -0.014748 0 -0 0</pose>
        <mass>0.00880254</mass>
        <inertia>
          <ixx>1.06448e-06</ixx>
          <ixy>-7.25387e-10</ixy>
          <ixz>-5.5521e-09</ixz>
          <iyy>8.71957e-07</iyy>
          <iyz>3.34074e-09</iyz>
          <izz>5.8784e-07</izz>
        </inertia>
      </inertial>
      <collision name='menique_link0_collision'>
        <pose>0 0 0 0 -0 0</pose>
        <geometry>
          <mesh>
            <scale>1 1 1</scale>
            <uri>../meshes/menique_link0.STL</uri>
          </mesh>
        </geometry>
      </collision>
      <visual name='menique_link0_visual'>
  <material>
    <ambient>0.25 0.00 0.30 1.0</ambient>
    <diffuse>0.25 0.00 0.30 1.0</diffuse>
    <specular>0.5 0.5 0.5 1.0</specular>
    <emissive>0 0 0 1.0</emissive>
  </material>
        <pose>0 0 0 0 -0 0</pose>
        <geometry>
          <mesh>
            <scale>1 1 1</scale>
            <uri>../meshes/menique_link0.STL</uri>
          </mesh>
        </geometry>
      </visual>
    </link>
    <joint name='joint_menique_1' type='revolute'>
      <pose relative_to='menique_link0'>0 -0.000695 -0.0281 0 -0 0</pose>
      <parent>menique_link0</parent>
      <child>menique_link1</child>
      <axis>
        <xyz>0 1 0</xyz>
        <limit>
          <lower>-1e+16</lower>
          <upper>1e+16</upper>
        </limit>
        <dynamics>
          <spring_reference>0</spring_reference>
          <spring_stiffness>0</spring_stiffness>
        </dynamics>
      </axis>
    </joint>
    <link name='menique_link1'>
      <pose relative_to='joint_menique_1'>0 0 0 0 -0 0</pose>
      <inertial>
        <pose>-0.000609 -0.010995 -0.013626 0 -0 0</pose>
        <mass>0.0074677</mass>
        <inertia>
          <ixx>6.7288e-07</ixx>
          <ixy>-9.6056e-11</ixy>
          <ixz>2.4674e-08</ixz>
          <iyy>6.2574e-07</iyy>
          <iyz>2.4801e-10</iyz>
          <izz>3.9564e-07</izz>
        </inertia>
      </inertial>
      <collision name='menique_link1_collision'>
        <pose>0 0 0 0 -0 0</pose>
        <geometry>
          <mesh>
            <scale>1 1 1</scale>
            <uri>../meshes/menique_link1.STL</uri>
          </mesh>
        </geometry>
      </collision>
      <visual name='menique_link1_visual'>
  <material>
    <ambient>0.25 0.00 0.30 1.0</ambient>
    <diffuse>0.25 0.00 0.30 1.0</diffuse>
    <specular>0.5 0.5 0.5 1.0</specular>
    <emissive>0 0 0 1.0</emissive>
  </material>
        <pose>0 0 0 0 -0 0</pose>
        <geometry>
          <mesh>
            <scale>1 1 1</scale>
            <uri>../meshes/menique_link1.STL</uri>
          </mesh>
        </geometry>
      </visual>
    </link>
    <joint name='joint_menique_2' type='revolute'>
      <pose relative_to='menique_link1'>0 -0.000975 -0.028 0 -0 0</pose>
      <parent>menique_link1</parent>
      <child>menique_link2</child>
      <axis>
        <xyz>0 1 0</xyz>
        <limit>
          <lower>-1e+16</lower>
          <upper>1e+16</upper>
        </limit>
        <dynamics>
          <spring_reference>0</spring_reference>
          <spring_stiffness>0</spring_stiffness>
        </dynamics>
      </axis>
    </joint>
    <link name='menique_link2'>
      <pose relative_to='joint_menique_2'>0 0 0 0 -0 0</pose>
      <inertial>
        <pose>-0.000425 -0.010032 -0.011482 0 -0 0</pose>
        <mass>0.00613512</mass>
        <inertia>
          <ixx>5.34284e-07</ixx>
          <ixy>4.89343e-11</ixy>
          <ixz>1.501e-08</ixz>
          <iyy>5.392e-07</iyy>
          <iyz>-4.52288e-10</iyz>
          <izz>2.36691e-07</izz>
        </inertia>
      </inertial>
      <collision name='menique_link2_collision'>
        <pose>0 0 0 0 -0 0</pose>
        <geometry>
          <mesh>
            <scale>1 1 1</scale>
            <uri>../meshes/menique_link2.STL</uri>
          </mesh>
        </geometry>
      </collision>
      <visual name='menique_link2_visual'>
  <material>
    <ambient>0.25 0.00 0.30 1.0</ambient>
    <diffuse>0.25 0.00 0.30 1.0</diffuse>
    <specular>0.5 0.5 0.5 1.0</specular>
    <emissive>0 0 0 1.0</emissive>
  </material>
        <pose>0 0 0 0 -0 0</pose>
        <geometry>
          <mesh>
            <scale>1 1 1</scale>
            <uri>../meshes/menique_link2.STL</uri>
          </mesh>
        </geometry>
      </visual>
    </link>
    <joint name='joint_pulgar_0' type='revolute'>
      <pose relative_to='base_link'>0.018291 -0.13588 0.129681 1.5708 -0.47347 -0</pose>
      <parent>base_link</parent>
      <child>pulgar_link0</child>
      <axis>
        <xyz>0 0 1</xyz>
        <limit>
          <lower>-1e+16</lower>
          <upper>1e+16</upper>
        </limit>
        <dynamics>
          <spring_reference>0</spring_reference>
          <spring_stiffness>0</spring_stiffness>
        </dynamics>
      </axis>
    </joint>
    <link name='pulgar_link0'>
      <pose relative_to='joint_pulgar_0'>0 0 0 0 -0 0</pose>
      <inertial>
        <pose>0.004274 0.035281 0.03492 0 -0 0</pose>
        <mass>0.0324581</mass>
        <inertia>
          <ixx>1.35094e-05</ixx>
          <ixy>-1.51351e-06</ixy>
          <ixz>9.14252e-07</ixz>
          <iyy>6.92053e-06</iyy>
          <iyz>4.18994e-06</iyz>
          <izz>9.69092e-06</izz>
        </inertia>
      </inertial>
      <collision name='pulgar_link0_collision'>
        <pose>0 0 0 0 -0 0</pose>
        <geometry>
          <mesh>
            <scale>1 1 1</scale>
            <uri>../meshes/pulgar_link0.STL</uri>
          </mesh>
        </geometry>
      </collision>
      <visual name='pulgar_link0_visual'>
  <material>
    <ambient>0.25 0.00 0.30 1.0</ambient>
    <diffuse>0.25 0.00 0.30 1.0</diffuse>
    <specular>0.5 0.5 0.5 1.0</specular>
    <emissive>0 0 0 1.0</emissive>
  </material>
        <pose>0 0 0 0 -0 0</pose>
        <geometry>
          <mesh>
            <scale>1 1 1</scale>
            <uri>../meshes/pulgar_link0.STL</uri>
          </mesh>
        </geometry>
      </visual>
    </link>
    <joint name='joint_pulgar_1' type='revolute'>
      <pose relative_to='pulgar_link0'>-0.016974 0.039947 -0.024949 -0.17928 -0.16915 -0.27411</pose>
      <parent>pulgar_link0</parent>
      <child>pulgar_link1</child>
      <axis>
        <xyz>0.52368 0.38683 0.75902</xyz>
        <limit>
          <lower>-1e+16</lower>
          <upper>1e+16</upper>
        </limit>
        <dynamics>
          <spring_reference>0</spring_reference>
          <spring_stiffness>0</spring_stiffness>
        </dynamics>
      </axis>
    </joint>
    <link name='pulgar_link1'>
      <pose relative_to='joint_pulgar_1'>0 0 0 0 -0 0</pose>
      <inertial>
        <pose>0.032966 0.035823 0.028152 0 -0 0</pose>
        <mass>0.0188</mass>
        <inertia>
          <ixx>3.50846e-06</ixx>
          <ixy>-5.45407e-07</ixy>
          <ixz>3.34377e-07</ixz>
          <iyy>2.33645e-06</iyy>
          <iyz>9.85584e-07</iyz>
          <izz>2.8012e-06</izz>
        </inertia>
      </inertial>
      <collision name='pulgar_link1_collision'>
        <pose>0 0 0 0 -0 0</pose>
        <geometry>
          <mesh>
            <scale>1 1 1</scale>
            <uri>../meshes/pulgar_link1.STL</uri>
          </mesh>
        </geometry>
      </collision>
      <visual name='pulgar_link1_visual'>
  <material>
    <ambient>0.25 0.00 0.30 1.0</ambient>
    <diffuse>0.25 0.00 0.30 1.0</diffuse>
    <specular>0.5 0.5 0.5 1.0</specular>
    <emissive>0 0 0 1.0</emissive>
  </material>
        <pose>0 0 0 0 -0 0</pose>
        <geometry>
          <mesh>
            <scale>1 1 1</scale>
            <uri>../meshes/pulgar_link1.STL</uri>
          </mesh>
        </geometry>
      </visual>
    </link>
    <joint name="fixed_to_world_joint" type="fixed">
      <parent>world</parent>  <!-- El parent es el "world" para anclarlo al mundo -->
      <child>base_link</child> <!-- El child es el enlace que quieres fijar -->
      <pose>0 0 0.5 0 0 0</pose> <!-- Ajusta la altura a 0.5 metros en el eje Z -->
    </joint>

  </model>
</sdf>
